>-*-*-*-*-*-*-<
LR: 5e-05, WD: 0.001, Seed: 42, BS: 1, Max Length: 60, Gradual Unfreeze: False, Discriminative Finetuning: False, Weight: None, Use Smaller Vocab: False, Accumulation Steps: 1
>-*-*-*-*-*-*-<
> /home/ubuntu/finBERT/hf_zero_shot_example.py(384)main()
-> with open(path, 'w') as f:
(Pdb) Some weights of GPT2ForSequenceClassification were not initialized from the model checkpoint at gpt2-xl and are newly initialized: ['score.weight']
You should probably TRAIN this model on a down-stream task to be able to use it for predictions and inference.
  0%|          | 0/6 [00:00<?, ?it/s]Training on batches...
Validation on batches...

  0%|          | 0/609 [00:00<?, ?it/s][A> /home/ubuntu/finBERT/hf_zero_shot_example.py(283)validation()
-> outputs = model(**batch)
(Pdb) {'input_ids': tensor([[ 5122,   287,    12, 18053, 13572, 14582,   284,   262,  7032,   286,
          2568,   837,  2831,   837,  7876,  1222, 15873,   290,  1660,  1222,
          2858,   220]], device='cuda:0'), 'attention_mask': tensor([[1, 1, 1, 1, 1, 1, 1, 1, 1, 1, 1, 1, 1, 1, 1, 1, 1, 1, 1, 1, 1, 1]],
       device='cuda:0'), 'labels': tensor([1], device='cuda:0')}
(Pdb)   0%|          | 0/609 [01:50<?, ?it/s]
  0%|          | 0/6 [01:50<?, ?it/s]
Traceback (most recent call last):
  File "hf_zero_shot_example.py", line 640, in <module>
    results = main(lr=lr, wd=wd, seed=seed, name=args.name, weight=weight, bs=bs, max_length=max_length, gradual_unfreeze=gradual_unfreeze, discriminate=discriminate, use_smaller_vocab=use_smaller_vocab, experiment_name=args.experiment_name, accumulation_steps=accumulation_steps)
  File "hf_zero_shot_example.py", line 384, in main
    with open(path, 'w') as f:
  File "hf_zero_shot_example.py", line 283, in validation
    outputs = model(**batch)
  File "hf_zero_shot_example.py", line 283, in validation
    outputs = model(**batch)
  File "/home/ubuntu/anaconda3/lib/python3.7/bdb.py", line 88, in trace_dispatch
    return self.dispatch_line(frame)
  File "/home/ubuntu/anaconda3/lib/python3.7/bdb.py", line 113, in dispatch_line
    if self.quitting: raise BdbQuit
bdb.BdbQuit
Traceback (most recent call last):
  File "/home/ubuntu/venv/bin/accelerate", line 8, in <module>
    sys.exit(main())
  File "/home/ubuntu/venv/lib/python3.7/site-packages/accelerate/commands/accelerate_cli.py", line 41, in main
    args.func(args)
  File "/home/ubuntu/venv/lib/python3.7/site-packages/accelerate/commands/launch.py", line 384, in launch_command
    simple_launcher(args)
  File "/home/ubuntu/venv/lib/python3.7/site-packages/accelerate/commands/launch.py", line 142, in simple_launcher
    raise subprocess.CalledProcessError(returncode=process.returncode, cmd=cmd)
subprocess.CalledProcessError: Command '['/home/ubuntu/venv/bin/python3.7', 'hf_zero_shot_example.py', '--name', 'hf_public_ckpt', '--weight', 'public_ckpt', '--lr', '5e-5', '--wd', '0.001', '--seed', '42', '--bs', '1', '--max_length', '60', '--gradual_unfreeze', 'False', '--discriminate', 'False', '--use_smaller_vocab', 'False', '--experiment_name', '10_13_21_gpt2small', '--accumulation_steps', '1']' returned non-zero exit status 1.
